Workbook

Sheet từ ghép n23
A1: 参加 | B1: THAM GIA | C1: さんか | D1: tham gia
A2: 参考 | B2: THAM KHẢO | C2: さんこう | D2: tham khảo
A3: 参戦 | B3: THAM CHIẾN | C3: さんせん | D3: tham chiến
A4: 乗車 | B4: THỪA XA | C4: じょうしゃ | D4: phương tiện giao thông
A5: 乗客 | B5: THỪA KHÁCH | C5: じょうきゃく | D5: hành khách
A6: 乾季 | B6: CAN QUÝ | C6: かんき | D6: mùa khô
A7: 乾杯 | B7: CAN BÔI | C7: かんぱい | D7: cạn ly
A8: 事件 | B8: SỰ KIỆN | C8: じけん | D8: sự kiện
A9: 事情 | B9: SỰ TÌNH | C9: じじょう | D9: tình trạng
A10: 事故 | B10: SỰ CỐ | C10: じこ | D10: Tai nạn
A11: 主人 | B11: CHỦ NHÂN | C11: しゅじん | D11: Người chồng
A12: 主義 | B12: CHỦ NGHĨA | C12: しゅぎ | D12: Chủ nghĩa
... A1612: 実験 | B1612: THỰC NGHIỆM | C1612: じっけん | D1612: Thực nghiệm, kinh nghiệm thực tế

Sheet N5
A1: 漢字 | B1: ひらがな | C1: Hán Việt | D1: Nghĩa | E1: Chưa thuộc | F1: Từ loại
A2: 私 | B2: わたし | C2: Tư | D2: Tôi | F2: N
A3: 私達 | B3: わたしたち | C3: Tư đạt | D3: Chúng tôi | F3: N
A4: 貴方 | B4: あなた | C4: Quý phương | D4: Bạn | F4: N
A5: 先生 | B5: せんせい | C5: Tiên sinh | D5: Cô, thầy giáo | F5: N
A6: 教師 | B6: きょうし | C6: Giáo sư | D6: Giáo viên | F6: N
A7: 実習生 | B7: じっしゅうせい | C7: Thực tập sinh | D7: Thực tập sinh | F7: N
A8: 研究者 | B8: けんきゅうしゃ | C8: Nghiên cứu giả | D8: Nhà nghiên cứu | F8: N
A9: 技術者 | B9: ぎじゅつしゃ | C9: Kỹ thuật giả | D9: Kỹ thuật viên | F9: N
A10: 留学生 | B10: りゅうがくせい | C10: Lưu học sinh | D10: Du học sinh | F10: N
A11: 学生 | B11: がくせい | C11: Học sinh | D11: Học sinh | F11: N
A12: 会社員/社員 | B12: かいしゃいん | C12: Hội xã viên | D12: Nhân viên công ty | F12: N
A13: 銀行員 | B13: ぎんこういん | C13: Ngân hàng viên | D13: Nhân viên ngân hàng | F13: N
... A24: 韓国 | B24: かんこく | C24: Hàn quốc | D24: Hàn Quốc | F24: N
A25: ベトナム | D25: Việt Nam | F25: N
A26: 日本 /にっぽん | B26: にほん | C26: Nhật bản | D26: Nhật Bản | F26: N
A27: 誰 | B27: だれ | C27: Thùy | D27: Ai | F27: N
A28: 本 | B28: ほん | C28: Bản | D28: Quyển sách | F28: N
A29: 辞書 | B29: じしょ | C29: Từ thư | D29: Từ điển | F29: N
A30: 雑誌 | B30: ざっし | C30: Tạp chí | D30: Tạp chí | F30: N
A31: 新聞 | B31: しんぶん | C31: Tân văn | D31: Báo | F31: N
A32: 紙 | B32: かみ | C32: Chỉ | D32: Giấy | F32: N
A33: 煙草 | B33: たばこ | C33: Yên thảo | D33: Thuốc lá | F33: N
A34: 灰皿 | B34: はいざら | C34: Hôi mãnh | D34: Gạt tàn thuốc lá | F34: N
A35: 箱 | B35: はこ | C35: Tương | D35: Hộp | F35: N
A36: 手紙 | B36: てがみ | C36: Thủ chỉ | D36: Thư | F36: N
A37: 手帳 | B37: てちょう | C37: Thủ trướng | D37: Sổ tay | F37: N
... A100: 一昨日 | B100: おととい | C100: Nhất tác minh | D100: Hôm kia | F100: N
A101: 昨日 | B101: きのう | D101: Hôm qua | F101: N
A102: 今日 | B102: きょう | D102: Hôm nay | F102: N
A103: 明日 | B103: あした | C103: Minh | D103: Ngày mai | F103: N
A104: 明後日 | B104: あっさて | C104: Minh hậu nhật | D104: Ngày kia | F104: N
A105: 今朝 | B105: けさ | C105: Kim triều | D105: Sáng nay | F105: N
A106: 今晩 | B106: こんばん | C106: Kim vãn | D106: Tối nay | F106: N
A107: 昼休み | B107: ひるやすみ | C107: Trú hưu | D107: Nghỉ trưa | F107: N
A108: 講義 | B108: こうぎ | C108: Giảng nghĩa | D108: Bài giảng | F108: N
A109: 日曜日 | B109: にちようび | C109: Nhật diệu | D109: Chủ nhật | F109: N
A110: 月曜日 | B110: けつようび | C110: Nguyệt | D110: Thứ 2 | F110: N
A111: 火曜日 | B111: かようび | C111: Hỏa | D111: Thứ 3 | F111: N
A112: 水曜日 | B112: すいようび | C112: Thủy | D112: Thứ 4 | F112: N
...

Sheet N4
A1: 漢字 | B1: ひらがな | C1: Hán Việt | D1: Nghĩa | E1: Chưa thuộc | F1: Từ loại
A2: 診る | B2: みる | C2: Chẩn | D2: Xem, khám bệnh | F2: V
A3: 探す、捜す | B3: さがす | C3: Thám, sưu | D3: Tìm, tìm kiếm | F3: V
A4: 遅れる | B4: おくれる | C4: Trì | D4: Chậm, muộn | F4: V
A5: 間に合う | B5: まにあう | C5: Gian hợp | D5: Kịp | F5: V
A6: やる | D6: Làm | F6: V
A7: 参加する | B7: さんかする | C7: Tham gia | D7: Tham gia, dự | F7: V
A8: 申し込む | B8: もうしこむ | C8: Thân nhập | D8: Đăng kí | F8: A
A9: 都合が良い | B9: つごうがいい | C9: Đô hợp lương | D9: Có time | F9: A
A10: 都合が悪い | B10: つごうがわるい | C10: Đô hợp ác | D10: Không có time | F10: A
A11: 気分が良い | B11: きぶんがいい | C11: Khí phân lương | D11: Cảm thấy tốt | F11: A
A12: 気分が悪い | B12: きぶんがわるい | C12: Khí phân ác | D12: Cảm thấy không tốt | F12: A
A13: 新聞社 | B13: しんぶんしゃ | C13: Tân văn xã | D13: Tòa soạn báo | F13: N
A14: 柔道 | B14: じゅうどう | C14: Nhu đạo | D14: Môn nhu đạo | F14: N
A15: 運動会 | B15: うんどうかい | C15: vận động hội | D15: Hội thi thể thao | F15: N
A16: 場所 | B16: ばしょ | C16: Trường sở | D16: Địa điểm | F16: N
A17: ～弁 | B17: べん | C17: Biện, biền | D17: Giọng, tiếng ~ | F17: N
A18: 今度 | B18: こんど | C18: Kim độ | D18: Lần tới | F18: N
... A44: 聞こえる | B44: きこえる | C44: Văn | D44: Nghe thấy | F44: V
A45: できます | D45: Được xây dựng | F45: V
A46: 開く | B46: ひらく | C46: Khai | D46: Mở (lớp học) | F46: V
A47: 鳥 | B47: とり | C47: Điểu | D47: Chim | F47: N
A48: 声 | B48: こえ | C48: Thanh | D48: Tiếng, giọng (人)
A49: 波 | B49: なみ | C49: Ba | D49: Sóng biển
A50: 花火 | B50: はなび | C50: Hoa hỏa | D50: Pháo hoa
A51: 景色 | B51: けしき | C51: Cảnh sắc | D51: Phong cảnh(風景phong cảnh )
A52: 昼間 | B52: ひるま | C52: Trú gian | D52: Time ban ngày
A53: 昔 | B53: むかし | C53: Tích | D53: Ngày xưa
A54: 道具 | B54: どうぐ | C54: Đạo cụ | D54: Dụng cụ, công cụ
A55: 自動販売機 | B55: じどうはんばいき | C55: Tự động phiến mại cơ | D55: Máy bán hàng tự động
A56: 通信販売 | B56: つうしんはんばい | C56: Thông tín phiến mại | D56: Thương mại viễn thông
A57: 台所 | B57: だいどころ | C57: Đài sở | D57: Bếp
A58: ～教室 | B58: きょうしつ | C58: Giáo thất | D58: Lớp học
A59: ～後 | B59: ご | C59: Hậu | D59: Sau ~
... A61: 他の | B61: ほかの | C61: Tha | D61: Khác ngoài ra
A62: はっきり | D62: Rõ, rõ ràng
A63: 殆ど | B63: ほとんど | C63: Đãi | D63: Hầu như, hầu hết
A64: 日曜大工 | B64: にちようだいく | C64: Nhật diệu đại công | D64: Thợ mộc chủ nhật
A65: 本棚 | B65: ほんだな | C65: Bản bằng | D65: Giá sách
A66: 夢 | B66: ゆめ | C66: Mộng | D66: Giấc mơ
...

Sheet ngữ pháp n4
A1: 第２６課
A2: 1
A3: V
A4: Aい Thể thường
A5: んです
A6: Aな Thể thường
A7: N ～だ à な
A10: ＊ Ý nghĩa: (nhấn mạnh ý muốn nói, muốn hỏi; dùng trong văn nói nhiều)
A11: ＊ Cách cấu tạo:
A13: Động từ dạng ngắn V る･V ない･V た
A14: Tính từ đuôi i ～い
A15: んです。
A16: Tính từ đuôi na ～な
A17: Danh từ
... A50: どうして 遅れたんですか。Tai sao anh lại đến muộn thế?
A52: 16
A53: _x000C_ FPT University Tiếng Nhật cơ sở 3
A54: Japanese Language Training Division Giải thích văn phạm
A55: * Chú ý: Đôi khi ．～んですか biểu thị sự ngạc nhiên, mối nghi ngờ hay sự tò mò sâu sắc. Tuy nhiên,
A56: nếu không dùng đúng thì có thể làm tổn thương người nghe. Vì thế nên cẩn thận khi dùng.
A57: しゃちょう かえ
A59: × 社 長 、帰らないんですか。Anh không về sao, giám đốc?
A61: (à Biểu hiện này có hàm ý trách móc, dễ dẫn đến thất lễ)
A62: しゃちょう かえ
A64: ○ 社 長 、帰りませんか。Anh không về sao, giám đốc?
A67: (2) Trong câu trần thuật: 「～んです。」
A68: Biểu hiện này thường dùng trong những trường hợp sau:
A69: a) Khi trả lời câu hỏi tại sao giống như ý C ở phần trên. (phía sau không còn から nữa)
... A105: * Chú ý: ～ていただけませんか chứ không phải là ～ていただきませんか。
A108: 17
A109: _x000C_ FPT University Tiếng Nhật cơ sở 3
A110: Japanese Language Training Division Giải thích văn phạm
A111: Ví dụ:
A112: に ほ ん ご てがみ か み
A114: 日本語で 手紙を 書いたんですが、見て いただけませんか。
A116: Tôi đã viết 1 bức thư bằng tiếng Nhật, anh/chị xem giúp tôi được không ạ?
A117: き つか かた わ おし
A119: コピー機の 使い方が 分からないんですが、教えて いただけませんか。
A121: Tôi không biết cách sử dụng máy photo, anh/chị chỉ giúp tôi được không ạ?
A124: 2.2 (cách hỏi cách làm, xin lời khuyên,
...

Sheet N3
A1: STT | B1: 漢字 | C1: Hán Việt | D1: ひらがな | E1: Nghĩa | F1: Chưa thuộc | G1: Từ loại
A2: 1 | B2: 男性 | C2: Nam tính | D2: だんせい | E2: Nam giới
A3: 2 | B3: 女性 | C3: Nữ tính | D3: じょせい | E3: Nữ giới
A4: 3 | B4: 理想 | C4: Lý tưởng | D4: りそう | E4: Lý tưởng
A5: 4 | B5: 高齢 | C5: Cao linh | D5: こうれい | E5: Cao tuổi
A6: 5 | B6: 年上 | C6: Niên thượng | D6: としうえ | E6: Hơn tuổi
A7: 6 | B7: 目上 | C7: Mục thượng | D7: めうえ | E7: Người trên
A8: 7 | B8: 敬語 | C8: Kính ngữ | D8: けいご | E8: Kính ngữ
A9: 8 | B9: 先輩 | C9: Tiền bối | D9: せんぱい | E9: Tiền bối
A10: 9 | B10: 後輩 | C10: Hậu bối | D10: こうはい | E10: Hậu bối
A11: 10 | B11: 職場 | C11: Chức trường | D11: しょくば | E11: Nơi làm việc
A12: 11 | B12: 上司 | C12: Thượng ty | D12: じょうし | E12: Cấp trên
A13: 12 | B13: 決定 | C13: Quyết định | D13: けってい | E13: Quyết định
... A87: 87 | B87: 約束する | C87: Ước thúc | D87: やくそくする | E87: Lời hứa
A88: 88 | B88: おしゃべりする | E88: Nói chuyện
A89: 89 | B89: 怒る | C89: Nộ | D89: おこる | E89: Tức giận
A90: 90 | B90: 遠慮する | C90: Viễn lự | D90: えんりょ | E90: Ngại ngần
A91: 91 | B91: 我慢する | C91: Ngã mạn | D91: がまんする | E91: Chịu đựng
A92: 92 | B92: 迷惑する | C92: Mê hoặc | D92: めいわくする | E92: Làm phiền
A93: 93 | B93: 捨てる | C93: Vứt | D93: すてる | E93: Vứt
A94: 94 | B94: 希望 | C94: Hi vọng | D94: きぼう | E94: Hi vọng
A95: 95 | B95: 夢 | C95: Mộng | D95: ゆめ | E95: Giấc mơ, ước mơ
A96: 96 | B96: 怖い | C96: Bố trong khủng bố | D96: こわい | E96: Đáng sợ
A97: 97 | B97: 賛成する | C97: Tán thành | D97: さんせいする | E97: Tán thành
A98: 98 | B98: 挙げる | C98: Cử | D98: あげる | E98: Giơ tay
A99: 99 | B99: 反対する | C99: Phản đối | D99: はんたいする | E99: Phản đối
A100: 100 | B100: 想像する | C100: Tưởng tượng | D100: そうぞう | E100: Tưởng tượng
... A243: 243 | B243: 離す | C243: Ly | D243: はなす | E243: Để xa ra, làm tránh ra
A244: 244 | B244: ぶつかる | E244: Bị đâm
A245: 245 | B245: ぶつける | E245: Đâm vào
A246: 246 | B246: 涙 | C246: Lệ | D246: なみだ | E246: Nước mắt châu lệ nước mắt
A247: 247 | B247: 溢れる | C247: Dật | D247: こぼれる | E247: Tràn ra ngập tràn đầy
A248: 248 | B248: 溢す | C248: Dật | D248: こぼす | E248: Làm tràn ra
A249: 249 | B249: 拭く | C249: Thức | D249: ふく | E249: Lau, chùi, gạt
A250: 250 | B250: 片付く | C250: Phiến phó | D250: かたづく | E250: Ngăn nắp
A251: 251 | B251: 片付ける | C251: Phiến phó | D251: かたづける | E251: Dọn dẹp
A252: 252 | B252: 包む | C252: Bao | D252: つつむ | E252: Bọc
A253: 253 | B253: 貼る | C253: Thiếp | D253: はる | E253: Dán
A254: 254 | B254: 無くなる | C254: Vô | D254: なくなる | E254: Bị mất
A255: 255 | B255: 無くす | C255: Vô | D255: なくす | E255: Làm mất
...

Sheet ngữ pháp n3
A1: 1.[Ngữ pháp N4] 受身形: Thể bị động
A2: A. Cách chia động từ thể bị động (受身：うけみ) từ thể từ điển:
A3: 1. Động từ nhóm 1: Chuyển đuôi う → あ + れる
A4: Ví dụ: 話す（はなす）→ 話される、言う（いう）→ 言われる、書く（かく）→ 書かれる
A5: 2. Động từ nhóm 2: Bỏ đuôi る → られる
A6: Ví dụ: 食べる（たべる）→ 食べられる、見る（みる）→ 見られる、教える（おしえる）→教えられる
A7: * Dạng bị động của động từ nhóm 2 giống với cách chia thể khả năng.
A8: 3. Động từ nhóm 3 (bất quy tắc)
A9: する → される 来る（くる）→ 来られる（こられる）→ giống với thể khả năng
A10: B. Cấu trúc:
A11: 1. Bị động trực tiếp (chỉ có 1 tân ngữ)
A12: Dạng chủ động: A は B を + động từ chủ động.
... A170:  [Chủ ngữ] + は/が + động từ kính ngữ
AL171: Khiêm Nhường Ngữ
A172: Làm＿します | AL172: いたします
A173: Có Mặt＿います | AL173: おります
A174: Đi＿行きます Đến ＿来ます | AL174: まいります うかがいます
A175: Xem＿見ます | AL175: はいけんします
A176: Nói＿言います | AL176: もうしあげます
A177: Ăn＿食べます Uống＿飲みます | AL177: いただきます
A178: Cho＿くれます
A179: Biết＿しります | AL179: ぞんじます ぞんじあげます
AL181: ご＋V+します お＋V+します
A182: Ko Dùng Với V 1 Âm Tiết | AL182: 会います＿Gặp àおめにかかり ます
AL183: 聞きます＿Hỏi àうかがいます
AL184: あげます＿Tặng àさしあげます
AL185: 見せます＿Cho Xem àおめにかけま
AL186: す
AL187: ありますàござ います
A189: Câu ví dụ:
A190: ① 山田さんは おそばを 召し上がりました。Anh Yamada đã ăn mì soba.
A191: ② 田中先生は いらっしゃいますか。Thầy Tanaka có ở đây không ạ?
A192: ③ 社長（しゃちょう）は ゴルフを なさいます。Giám đốc chơi golf.
A193: ④ アンさんは インドへ 出張（しゅっちょう）なさいます。Anh An sẽ đi công tác ở Ấn Độ.
A194: 2. Với những động từ không có dạng kính ngữ đặc biệt (ngoài mục 1 ở trên):
A195: Mẫu câu 1: [Chủ ngữ] + は/が + お + động từ thể ます(bỏ ます) + に なります。
A196: * Lưu ý: Mẫu câu 1 này không dùng với động từ nhóm 3 và những động từ nhóm 2 chỉ có 1 âm tiết phía trước đuôi 「る」 như 「いる」、「出る（でる）」、「着る（きる）」
A197: ① 先生は もう おかえり に なりました。
A198: → Thầy giáo đã về rồi.
A199: ② 部長（ぶちょう）は たばこを お吸(す)いに なりません。
...

Sheet N2
A1: Hán Tự | B1: Cách Đọc | C1: Ý Nghĩa | D1: Âm Hán
A2: 人生 | B2: じんせい | C2: Cuộc sống | D2: =VLOOKUP(A2,'N2.for ref'!B$2:E$1266,3,0) -> NHÂN SINH
A3: 人間 | B3: にんげん | C3: Nhân gian | D3: =VLOOKUP(A3,'N2.for ref'!B$2:E$1266,3,0) -> NHÂN GIAN
A4: 人 | B4: ひと | C4: Người | D4: =VLOOKUP(A4,'N2.for ref'!B$2:E$1266,3,0) -> NHÂN
A5: 祖先 | B5: そせん | C5: Tổ tiên | D5: =VLOOKUP(A5,'N2.for ref'!B$2:E$1266,3,0) -> TỔ TIÊN
A6: 親戚 | B6: しんせき | C6: Họ hàng | D6: =VLOOKUP(A6,'N2.for ref'!B$2:E$1266,3,0) -> THÂN THÍCH
A7: 夫婦 | B7: ふうふ | C7: Vợ chồng | D7: =VLOOKUP(A7,'N2.for ref'!B$2:E$1266,3,0) -> PHU PHỤ
A8: 長男 | B8: ちょうなん | C8: Trưởng nam | D8: =VLOOKUP(A8,'N2.for ref'!B$2:E$1266,3,0) -> TRƯỞNG NAM
A9: 主人 | B9: しゅじん | C9: Chủ cửa hàng, chồng | D9: =VLOOKUP(A9,'N2.for ref'!B$2:E$1266,3,0) -> CHỦ NHÂN
A10: 双子 | B10: ふたご | C10: Sinh đôi | D10: =VLOOKUP(A10,'N2.for ref'!B$2:E$1266,3,0) -> SONG TỬ
A11: 迷子 | B11: まいご | C11: Trẻ bị lạc | D11: =VLOOKUP(A11,'N2.for ref'!B$2:E$1266,3,0) -> MÊ TỬ
A12: 他人 | B12: たにん | C12: Người khác | D12: =VLOOKUP(A12,'N2.for ref'!B$2:E$1266,3,0) -> THA NHÂN
A13: 敵 | B13: てき | C13: Kẻ thù | D13: =VLOOKUP(A13,'N2.for ref'!B$2:E$1266,3,0) -> ĐỊCH
... A38: 全身 | B38: ぜんしん | C38: Toàn thân | D38: =VLOOKUP(A38,'N2.for ref'!B$2:E$1266,3,0) -> TOÀN THÂN
A39: しわ | B39: しわ | C39: Nếp nhăn
A40: 服装 | B40: ふくそう | C40: Quần áo, trang phục | D40: =VLOOKUP(A40,'N2.for ref'!B$2:E$1266,3,0) -> PHỤC TRANG
A41: 礼 | B41: れい | C41: lễ, cảm ơn | D41: LỄ
A42: 世辞 | B42: せじ | C42: Nịnh, ca tụng | D42: =VLOOKUP(A42,'N2.for ref'!B$2:E$1266,3,0) -> GIỚI TỪ
A43: 言い訳 | B43: いいわけ | C43: Giải thích, lý do lý trấu | D43: =VLOOKUP(A43,'N2.for ref'!B$2:E$1266,3,0) -> NGÔN DỊCH
A44: 話題 | B44: わだい | C44: Chủ đề | D44: =VLOOKUP(A44,'N2.for ref'!B$2:E$1266,3,0) -> THOẠI ĐỀ
A45: 秘密 | B45: ひみつ | C45: Bí mật | D45: =VLOOKUP(A45,'N2.for ref'!B$2:E$1266,3,0) -> BÍ MẬT
A46: 尊敬 | B46: そんけい | C46: Tôn trọng, tôn kính | D46: =VLOOKUP(A46,'N2.for ref'!B$2:E$1266,3,0) -> TÔN KÍNH
A47: 謙遜 | B47: けんそん | C47: Khiêm tốn | D47: =VLOOKUP(A47,'N2.for ref'!B$2:E$1266,3,0) -> KHIÊM TỐN
A48: 期待 | B48: きたい | C48: Mong chờ, mong đợi | D48: =VLOOKUP(A48,'N2.for ref'!B$2:E$1266,3,0) -> KÌ ĐÃI
A49: 苦労 | B49: くろう | C49: Lo lắng, vất vả | D49: =VLOOKUP(A49,'N2.for ref'!B$2:E$1266,3,0) -> KHỔ LAO
A50: 意志 | B50: いし | C50: ý chí | D50: Ý CHÍ
A51: 感情 | B51: かんじょう | C51: Biểu cảm, tâm trạng | D51: =VLOOKUP(A51,'N2.for ref'!B$2:E$1266,3,0) -> CẢM TÌNH
A52: 材料 | B52: ざいりょう | C52: Nguyên liệu (nấu ăn) | D52: =VLOOKUP(A52,'N2.for ref'!B$2:E$1266,3,0) -> TÀI LIỆU
A53: 石 | B53: いし | C53: Đá | D53: =VLOOKUP(A53,'N2.for ref'!B$2:E$1266,3,0) -> THẠCH
A54: 紐 | B54: ひも | C54: Sợi dây | D54: =VLOOKUP(A54,'N2.for ref'!B$2:E$1266,3,0) -> NỮU
A55: 券 | B55: けん | C55: Vé | D55: =VLOOKUP(A55,'N2.for ref'!B$2:E$1266,3,0) -> KHOÁN
A56: 名簿 | B56: めいぼ | C56: Danh bạ, danh sách | D56: =VLOOKUP(A56,'N2.for ref'!B$2:E$1266,3,0) -> DANH BỘ
A57: 表 | B57: ひょう | C57: Bảng biểu | D57: =VLOOKUP(A57,'N2.for ref'!B$2:E$1266,3,0) -> BIỂU
A58: 針 | B58: はり | C58: Cái kim | D58: =VLOOKUP(A58,'N2.for ref'!B$2:E$1266,3,0) -> CHÂM
A59: 栓 | B59: せん | C59: Cái nắp | D59: =VLOOKUP(A59,'N2.for ref'!B$2:E$1266,3,0) -> XUYÊN
A60: 湯気 | B60: ゆげ | C60: Hơi, khí | D60: =VLOOKUP(A60,'N2.for ref'!B$2:E$1266,3,0) -> THANG KHÍ
A61: 日当たり | B61: ひあたり | C61: nơi có ánh sáng chiếu vào | D61: NHẬT ĐƯƠNG
A62: 空 | B62: から | C62: Trống rỗng | D62: =VLOOKUP(A62,'N2.for ref'!B$2:E$1266,3,0) -> KHÔNG
A63: 斜め | B63: ななめ | C63: nghiêng | D63: =VLOOKUP(A63,'N2.for ref'!B$2:E$1266,3,0) -> TÀ
A64: = | B64: りれき | C64: lý lịch | D64: =VLOOKUP(A64,'N2.for ref'!B$2:E$1266,3,0) -> #N/A
...

Sheet ngữ pháp n2
A1: 完全マスター 日本語能力試験 ２級 文法 阮登貴
A6: 完全マスター
A7: 日本語能力試験２級
A8: 文法
A13: 編集・翻訳 阮登貴 武氏河宣
A14: 神戸・河内 ２００８
A15: 1
A19: Chia sẻ tài liệu : Chiasemoi.com
A20: _x000C_完全マスター 日本語能力試験 ２級 文法 阮登貴
A25: 目次
A26: １ ～として（は）／～としても／～としての ............................................................................................. 7
A27: ２ ～とともに..................................................................................................................................................... 7
A28: ３ ～において（は）／～においても／～における ..................................................................................... 8
A29: ４ ～に応じて／～に応じ／～に応じた ......................................................................................................... 8
A30: ５ ～にかわって／～にかわり ......................................................................................................................... 8
A31: ６ ～に比べて／～に比べ ................................................................................................................................. 9
A32: ７ ～にしたがって／～にしたがい 従い／したがい ............................................................................. 9
A33: ８ ～につれて／～につれ ................................................................................................................................. 9
A34: ９ ～に対して（は）／～に対し／～に対しても／～に対する ............................................................... 10
... A63: ３６ ～一方だ................................................................................................................................................... 22
A64: 2
A65: _x000C_完全マスター 日本語能力試験 ２級 文法 阮登貴
A67: ３７ ～おそれがある ....................................................................................................................................... 22
A68: ３８ ～ことになっている ............................................................................................................................... 22
A69: ３９ ～ことはない........................................................................................................................................... 23
A70: ４０ ～しかない............................................................................................................................................... 23
A71: ４１ ～ということだ ....................................................................................................................................... 23
A72: ４２ ～まい／～まいか ................................................................................................................................... 24
A73: ４３ ～わけがない／～わけはない ............................................................................................................... 24
A74: ４４ ～わけにはいかない／～わけにもいかない ....................................................................................... 25
A75: ４５ ～から～にかけて ................................................................................................................................... 25
A76: ４６ たとえ～ても／たとえ～でも ............................................................................................................... 26
A77: ４７ ～さえ～ば............................................................................................................................................... 26
... A107: ７５ ～あまり................................................................................................................................................... 36
A108: 3
A109: _x000C_完全マスター 日本語能力試験 ２級 文法 阮登貴
A111: ７６ ～一方／～一方で（は） ....................................................................................................................... 36
A112: ７７ ～上で（は）／～上の／～上でも／～上での ................................................................................... 37
A113: ７８ ～限り（は）／～かぎりでは／～ないかぎり（は） ....................................................................... 37
A114: ７９ ～（か）と思うと／～（か）と思ったら ........................................................................................... 39
...

Sheet N1
A2: 1 | B2: 青春 | C2: せいしゅん | D2: thanh xuân
B3: 青春時代 | C3: せいしゅんじだい | D3: tuổi thanh xuân, tuổi trẻ
A4: 2 | B4: 晩年 | C4: ばんねん | D4: cuối đời, tuổi xế bóng
B5: 最晩年 | C5: さいばんねん | D5: những năm cuối đời
A6: 3 | B6: 葬式 | C6: そうしき | D6: tang lễ, đám tang
A7: 4 | B7: 世帯 | C7: せたい | D7: hộ gia đình
B8: 世帯主 | C8: せたいぬし | D8: chủ hộ
B9: 世帯数 | C9: せたいすう | D9: số lượng hộ gia đình
B10: 二世帯 | C10: にせたい | D10: 2 hộ gia đình
A11: 5 | B11: 世間 | C11: せけん | D11: thế gian, xã hội
B12: 世の中 | C12: よのなか | D12: xã hội
B13: 世間体 | C13: せけんてい | D13: miệng lưỡi thế gian
A14: 6 | B14: 庶民 | C14: しょみん | D14: dân đen, dân thường
B15: 庶民的 | C15: しょみんてき | D15: thông thường, tự nhiên, bình thường, mang tính phổ thông
B16: 庶民階級 | C16: しょみんかいきゅう | D16: giai cấp nhân dân
A17: 7 | B17: おんぶする | D17: ①địu, cõng trên lưng ②phụ thuộc, sống nhờ (実家に)
B18: 抱っこする | C18: だっこする | D18: ôm,ẵm trên tay
A19: 8 | B19: 片言 | C19: かたこと | D19: ① nói bập bõm, nói đứt đoạn, nói không trôi chảy ② tám chuyện
A20: 9 | B20: 夜更かし | C20: よふかし | D20: thức khuya
B21: 夜更かし（を）する | D21: thức khuya
B22: 夜更け | C22: よふけ | D22: Đêm khuya
A23: 10 | B23: 家出 | C23: いえで | D23: ① bỏ nhà ra đi ② đi ra khỏi nhà
B24: 家出する | D24: bỏ nhà ra đi
A25: 11 | B25: 戸締り(を)する | C25: とじまり | D25: khóa cửa
A26: 12 | B26: ずぶ濡れ | C26: ずぶぬれ | D26: ướt sũng
A27: 13 | B27: 顔つき | C27: かおつき | D27: vẻ mặt, nét mặt
A28: 14 | B28: 身なり | C28: みなり | D28: diện mạo
B29: 身なりをする | D29: thể hiện diện mạo
B30: 身なりがいい⇔悪い | D30: diện mạo tốt ⇔ xấu
A31: 15 | B31: 身の回り | C31: みのまわり | D31: những thứ xung quanh bản thân
B32: 身の回りのこと | D32: những việc thường ngày
A33: 16 | B33: 身振り | C33: みぶり | D33: Điệu bộ, cử chỉ
A34: 17 | B34: 良心 | C34: りょうしん | D34: lương tâm
B35: 良心がある⇔ない | D35: có lương tâm ⇔ không có lương tâm
B36: 良心が痛む | D36: đau đớn lương tâm
B37: 良心が恥じる | C37: はじる | D37: lương tâm xấu hổ
B38: 良心の呵責 | C38: かしゃく | D38: sự cắn rứt lương tâm
A39: 18 | B39: 素質 | C39: そしつ | D39: tố chất, năng khiếu （素質+努力＝才能）
A40: 19 | B40: 好意 | C40: こうい | D40: hảo ý, lòng tốt
B41: 敵意 | C41: てきい | D41: sự thù địch
...

Sheet ngữ pháp n1
A16: 日本語能力試験一級文法 阮登貴
A21: 日本語能力試験一級
A22: 文法
A27: 編集・翻訳 阮登貴 武氏河宣
A28: 神戸・河内 ２００８
A29: ©dangquybk@gmail.com
A30: (Powered by jlpt.info, copyright reserved 2007)
A35: 1
A36: _x000C_日本語能力試験一級文法 阮登貴
A40: 目次
A41: 1. A あっての B......................................................................................................................................... 5
A42: 2. A いかんで/では/によっては B、B は A いかんだ A のいかんによらず/かかわらず B............ 5
A43: 3. A う(意向形)が/と B A う(意向形)が A まいが/A う(意向形)と A まいと B................................. 5
A44: 4. A う(意向形)にも A(可能形)ない ....................................................................................................... 6
A45: 5. A 限りだ ................................................................................................................................................ 7
A46: 6. A(た)が最後 B ....................................................................................................................................... 7
A47: 7. A かたがた B......................................................................................................................................... 7
A48: 8. A かたわら B......................................................................................................................................... 8
A49: 9. A がてら B............................................................................................................................................. 8
A50: 10. A が早いか B......................................................................................................................................... 9
... A77: 37. A といい B といい.............................................................................................................................. 20
A78: 2
A79: _x000C_日本語能力試験一級文法 阮登貴
A80: 38. A というところだ/といったところだ ............................................................................................. 20
A81: 39. A といえども B................................................................................................................................... 21
A82: 40. A といったらない/といったらありはしない(ありゃしない)....................................................... 21
A83: 41. A と思いきや B................................................................................................................................... 21
A84: 42. A ときたら B....................................................................................................................................... 22
A85: 43. A ところを B....................................................................................................................................... 22
A86: 44. A としたところで/としたって/にしたところで/にしたって B.................................................... 23
A87: 45. A とは .................................................................................................................................................. 23
A88: 46. A とはいえ B....................................................................................................................................... 23
A89: 47. A とばかりに B................................................................................................................................... 24
A90: 48. A ともなく/ともなしに(していると/していたら).......................................................................... 24
... A119: 77. A ばそれまでだ .................................................................................................................................. 36
A120: 3
A121: _x000C_日本語能力試験一級文法 阮登貴
A122: 78. ひとり A だけでなく/ひとり A のみならず.................................................................................... 36
A123: 79. A べからず/べからざる ..................................................................................................................... 37
A124: 80. A べく .................................................................................................................................................. 37
...

Sheet N2.for ref
A1: STT | B1: 漢字 | C1: ひらがな | D1: Hán Việt | E1: Nghĩa | F1: Bổ sung
A2: 1 | B2: 人生 | C2: じんせい | D2: NHÂN SINH | E2: Cuộc sống | F2: =+VLOOKUP(B2,'N2'!$A$2:$D$1287,1,0) -> 人生
A3: 2 | B3: 一生 | C3: いっせい | D3: NHẤT SINH | E3: Một đời | F3: =+VLOOKUP(B3,'N2'!$A$2:$D$1287,1,0) -> #N/A | I3: どだい
A4: 3 | B4: 生涯 | C4: しょうがい | D4: SINH NHAI | E4: Sinh nhai, sự nghiệp | F4: =+VLOOKUP(B4,'N2'!$A$2:$D$1287,1,0) -> #N/A
A5: 4 | B5: 人間 | C5: にんげん | D5: NHÂN GIAN | E5: Nhân gian | F5: =+VLOOKUP(B5,'N2'!$A$2:$D$1287,1,0) -> 人間
A6: 5 | B6: 人物 | C6: じんぶつ | D6: NHÂN VẬT | E6: Nhân vật (con người) | F6: =+VLOOKUP(B6,'N2'!$A$2:$D$1287,1,0) -> 人物
A7: 6 | B7: 平等 | C7: へいとう | D7: BÌNH ĐẲNG | E7: Bình đẳng | F7: =+VLOOKUP(B7,'N2'!$A$2:$D$1287,1,0) -> #N/A
A8: 7 | B8: 人 | C8: ひと | D8: NHÂN | E8: Người | F8: =+VLOOKUP(B8,'N2'!$A$2:$D$1287,1,0) -> 人
A9: 8 | B9: 人類 | C9: じんるい | D9: NHÂN LOẠI | E9: Nhân loại | F9: =+VLOOKUP(B9,'N2'!$A$2:$D$1287,1,0) -> #N/A
A10: 9 | B10: 祖先 | C10: そせん | D10: TỔ TIÊN | E10: Tổ tiên | F10: =+VLOOKUP(B10,'N2'!$A$2:$D$1287,1,0) -> 祖先
A11: 10 | B11: 発生 | C11: はっせい | D11: PHÁT SINH | E11: Phát sinh | F11: =+VLOOKUP(B11,'N2'!$A$2:$D$1287,1,0) -> 発生
A12: 11 | B12: 親戚 | C12: しんせき | D12: THÂN THÍCH | E12: Họ hàng | F12: =+VLOOKUP(B12,'N2'!$A$2:$D$1287,1,0) -> 親戚
A13: 12 | B13: 親類 | C13: しんるい | D13: THÂN LOẠI | E13: Họ hàng | F13: =+VLOOKUP(B13,'N2'!$A$2:$D$1287,1,0) -> #N/A
A14: 13 | B14: 親族 | C14: しんぞく | D14: THÂN TỘC | E14: Họ hàng | F14: =+VLOOKUP(B14,'N2'!$A$2:$D$1287,1,0) -> #N/A
A15: 14 | B15: 夫婦 | C15: ふうふ | D15: PHU PHỤ | E15: Vợ chồng | F15: =+VLOOKUP(B15,'N2'!$A$2:$D$1287,1,0) -> 夫婦
... A83: 82 | B83: 玄関 | C83: げんかん | D83: HUYỀN QUAN | E83: Cửa ra vào | F83: =+VLOOKUP(B83,'N2'!$A$2:$D$1287,1,0) -> #N/A
A84: 83 | B84: しわ | C84: しわ | E84: Nếp Nhăn | F84: =+VLOOKUP(B84,'N2'!$A$2:$D$1287,1,0) -> #N/A
A85: 84 | B85: お年を取る | C85: おとしをとる | D85: NIÊN THỦ | E85: Về già, tuổi già | F85: =+VLOOKUP(B85,'N2'!$A$2:$D$1287,1,0) -> #N/A
A86: 85 | B86: 服装 | C86: ふくそう | D86: PHỤC TRANG | E86: Quần áo, trang phục | F86: =+VLOOKUP(B86,'N2'!$A$2:$D$1287,1,0) -> 服装
A87: 86 | B87: 面接 | C87: めんせつ | D87: DIỆN TIẾP | E87: Phỏng vấn | F87: =+VLOOKUP(B87,'N2'!$A$2:$D$1287,1,0) -> #N/A
A88: 87 | B88: お礼 | C88: おれい | D88: LỄ | E88: Lễ, cảm ơn | F88: =+VLOOKUP(B88,'N2'!$A$2:$D$1287,1,0) -> #N/A
A89: 88 | B89: お辞儀 | C89: おじぎ | D89: TỪ NGHI | E89: Cúi chào | F89: =+VLOOKUP(B89,'N2'!$A$2:$D$1287,1,0) -> #N/A
A90: 89 | B90: 述べる | C90: のべる | D90: THUẬT | E90: Phát biểu, thuật lại | F90: =+VLOOKUP(B90,'N2'!$A$2:$D$1287,1,0) -> 述べる
A91: 90 | B91: 世辞 | C91: せじ | D91: GIỚI TỪ | E91: Nịnh, ca tụng | F91: =+VLOOKUP(B91,'N2'!$A$2:$D$1287,1,0) -> 世辞
A92: 91 | B92: 言い訳 | C92: いいわけ | D92: NGÔN DỊCH | E92: Giải thích, lý do lý trấu | F92: =+VLOOKUP(B92,'N2'!$A$2:$D$1287,1,0) -> 言い訳
A93: 92 | B93: 認め | C93: みとめ | D93: XÁC | E93: Thừa nhận | F93: =+VLOOKUP(B93,'N2'!$A$2:$D$1287,1,0) -> #N/A
A94: 93 | B94: 話題 | C94: わだい | D94: THOẠI ĐỀ | E94: Chủ đề | F94: =+VLOOKUP(B94,'N2'!$A$2:$D$1287,1,0) -> 話題
A95: 94 | B95: 豊富 | C95: ほうふ | D95: PHONG PHÚ | E95: Phong phú | F95: =+VLOOKUP(B95,'N2'!$A$2:$D$1287,1,0) -> #N/A
A96: 95 | B96: 秘密 | C96: ひみつ | D96: BÍ MẬT | E96: Bí mật | F96: =+VLOOKUP(B96,'N2'!$A$2:$D$1287,1,0) -> 秘密
... A211: 210 | B211: 泣く | C211: なく | D211: KHẤP | E211: Khóc | F211: =+VLOOKUP(B211,'N2'!$A$2:$D$1287,1,0) -> #N/A
A212: 211 | B212: がっかりする | C212: がっかりする | E212: Thất vọng | F212: =+VLOOKUP(B212,'N2'!$A$2:$D$1287,1,0) -> がっかりする
A213: 212 | B213: 励ます | C213: はげます | D213: LỆ | E213: Động viên | F213: =+VLOOKUP(B213,'N2'!$A$2:$D$1287,1,0) -> 励ます
A214: 213 | B214: 頷く | C214: うなずく | D214: HẠM | E214: Gật đầu | F214: =+VLOOKUP(B214,'N2'!$A$2:$D$1287,1,0) -> 頷く
A215: 214 | B215: 張り切る | C215: はりきる | D215: TRƯƠNG | E215: Hăm hở, chăm chỉ làm việc | F215: =+VLOOKUP(B215,'N2'!$A$2:$D$1287,1,0) -> 張り切る
A216: 215 | B216: 威張る | C216: いばる | D216: UY TRƯƠNG | E216: Kiêu ngạo | F216: =+VLOOKUP(B216,'N2'!$A$2:$D$1287,1,0) -> 威張る
A217: 216 | B217: 怒鳴る | C217: どなる | D217: NỘ MINH | E217: Hét lên, gào lên | F217: =+VLOOKUP(B217,'N2'!$A$2:$D$1287,1,0) -> 怒鳴る
A218: 217 | B218: 暴れる | C218: あばれる | D218: BẠO | E218: Bạo lực, nổi giận | F218: =+VLOOKUP(B218,'N2'!$A$2:$D$1287,1,0) -> 暴れる
A219: 218 | B219: しゃがむ | C219: しゃがむ | E219: Ngồi chơi, ngồi xổm | F219: =+VLOOKUP(B219,'N2'!$A$2:$D$1287,1,0) -> しゃがむ
A220: 219 | B220: 退く | C220: どく | D220: THOÁI | E220: Tránh ra | F220: =+VLOOKUP(B220,'N2'!$A$2:$D$1287,1,0) -> 退く
A221: 220 | B221: 退ける | C221: どける | D221: THOÁI | E221: Đuổi khỏi, đuổi đi | F221: =+VLOOKUP(B221,'N2'!$A$2:$D$1287,1,0) -> 退ける
...

Sheet Từ láy
B1: うとうと | C1: うとうと | D1: ngủ gật
B2: はらはら | C2: はらはら | D2: áy náy, run rẩy
B3: ぺらぺら | C3: ぺらぺら | D3: lưu loát, trôi chảy
B4: のろのろ | C4: のろのろ | D4: chậm chạp, lề mề
B5: ぼろぼろ | C5: ぼろぼろ | D5: rách tơi tả, te tua
B6: ますます | C6: ますます | D6: ngày càng, hơn nữa
B7: するする | C7: するする | D7: một cách trôi chảy, nhanh chóng
B8: とうとう | C8: とうとう | D8: cuối cùng, kết cục, sau cùng
B9: そわそわ | C9: そわそわ | D9: không yên, hoang mang
B10: まずまず | C10: まずまず | D10: kha khá, tàm tạm
B11: すらすら | C11: すらすら | D11: trơn chu, trôi chảy
B12: たびたび | C12: たびたび | D12: thường xuyên, lập lại nhiều lần
... B75: ぶらぶら | C75: ぶらぶら | D75: quanh quẩn, đung đưa (đồ vật)

Sheet Trợ từ
A1: 1 | B1: 非常 | C1: ひじょうに | D1: Rất
A2: 2 | B2: 大変（に） | C2: たいへん | D2: Cực
A3: 3 | B3: ほとんど | C3: ほとんど | D3: Gần như hoàn toàn
A4: 4 | B4: 大体 | C4: だいたい | D4: Đại khái
A5: 5 | B5: かなり | C5: かなり | D5: Khá
A6: 6 | B6: ずいぶん | C6: ずいぶん | D6: Khá
A7: 7 | B7: 結構 | C7: けっこう | D7: Khá, tốt, đủ
A8: 8 | B8: だいぶ だいぶん | C8: 大分 | D8: Hầu như
A9: 9 | B9: もっと | C9: もっと | D9: Hơn nữa
A10: 10 | B10: すっかり | C10: すっかり | D10: Toàn bộ
A11: 11 | B11: いっぱい | C11: いっぱい | D11: Đầy, nhiều
A12: 12 | B12: ぴったり | C12: ぴったり | D12: Vừa vặn, đúng
... A189: 189 | B189: いわゆる | C189: いわゆる | D189: gọi là, thường gọi là

Sheet bộ thủ
A1: BỘ THỦ | B1: TÊN BỘ | C1: Ý NGHĨA
A2: 一 | B2: nhất | C2: số một
A3: 〡 | B3: cổn | C3: nét sổ
A4: 丶 | B4: chủ | C4: nét phẩy
A5: 丿 | B5: phiệt | C5: nét sổ
A6: 乙 | B6: ất | C6: can thứ 2
A7: 亅 | B7: quyết | C7: nét móc
A8: 二 | B8: nhị | C8: số hai
A9: 亠 | B9: đầu | C9: bộ đầu
A10: 人 | B10: nhân | C10: người
A11: 亻 | B11: nhân đứng | C11: dùng để ghép
A12: 儿 | B12: nhi | C12: trẻ con
... A206: 色 | B206: sắc | C206: màu sắc

Sheet Sheet3
